<?xml version="1.0" ?>

<robot name="XYZActuatedBlock">
  <link name="base_link"/>
  <link name="base_link_2"/>
  <link name="base_link_3"/>

  <link name="block_actual">
    <inertial>
      <mass value="1"/>
      <origin xyz="0 0 0"/>
      <inertia ixx="1" ixy="0.0" ixz="0.0" iyy="1" iyz="0.0" izz="1"/>
    </inertial>
    <visual>
      <origin rpy="0 0 0" xyz="0 0 0"/>
      <geometry>
        <sphere radius="0.2"/>
      </geometry>
      <material name="blue">
	    <color rgba="0 0 1 1" />
      </material>
    </visual>
    <collision>
      <origin rpy="0 0 0" xyz="0 0 0"/>
      <geometry>
        <sphere radius="0.2"/>
      </geometry>
    </collision>      
  </link>
  
  <frame link="block_actual" name="body" rpy="0 0 0" xyz="0 0 0" />
  
  <joint name="block_x" type="prismatic">
    <origin rpy="0 0 0" xyz="0 0 0.0"/>
    <parent link="base_link"/>
    <child link="block_actual"/>
    <limit lower="-inf" upper="inf"/>
    <axis xyz="1 0 0"/>
  </joint>
  
  <joint name="block_y" type="prismatic">
    <origin rpy="0 0 0" xyz="0 0 0.0"/>
    <parent link="base_link_2"/>
    <child link="block_actual"/>
    <limit lower="-inf" upper="inf"/>
    <axis xyz="0 1 0"/>
  </joint>

  <joint name="block_z" type="prismatic">
    <origin rpy="0 0 0" xyz="0 0 0.0"/>
    <parent link="base_link_3"/>
    <child link="block_actual"/>
    <limit lower="-inf" upper="inf"/>
    <axis xyz="0 0 1"/>
  </joint>
</robot>

